[2023-02-12T22:08:51.954+0200] {taskinstance.py:1171} INFO - Dependencies all met for <TaskInstance: test_process_sales.ds manual__2023-02-12T20:08:15.381483+00:00 [queued]>
[2023-02-12T22:08:51.960+0200] {taskinstance.py:1171} INFO - Dependencies all met for <TaskInstance: test_process_sales.ds manual__2023-02-12T20:08:15.381483+00:00 [queued]>
[2023-02-12T22:08:51.960+0200] {taskinstance.py:1368} INFO - 
--------------------------------------------------------------------------------
[2023-02-12T22:08:51.960+0200] {taskinstance.py:1369} INFO - Starting attempt 2 of 4
[2023-02-12T22:08:51.961+0200] {taskinstance.py:1370} INFO - 
--------------------------------------------------------------------------------
[2023-02-12T22:08:51.965+0200] {taskinstance.py:1389} INFO - Executing <Task(PythonOperator): ds> on 2023-02-12 20:08:15.381483+00:00
[2023-02-12T22:08:51.969+0200] {standard_task_runner.py:52} INFO - Started process 88719 to run task
[2023-02-12T22:08:51.973+0200] {standard_task_runner.py:79} INFO - Running: ['airflow', 'tasks', 'run', 'test_process_sales', 'ds', 'manual__2023-02-12T20:08:15.381483+00:00', '--job-id', '3687', '--raw', '--subdir', 'DAGS_FOLDER/process_sales/main.py', '--cfg-path', '/var/folders/1g/4w5x68gx3d92wgygb97jqbd40000gp/T/tmp3nlxf86t', '--error-file', '/var/folders/1g/4w5x68gx3d92wgygb97jqbd40000gp/T/tmpigzsr5e8']
[2023-02-12T22:08:51.974+0200] {standard_task_runner.py:80} INFO - Job 3687: Subtask ds
[2023-02-12T22:08:52.000+0200] {task_command.py:371} INFO - Running <TaskInstance: test_process_sales.ds manual__2023-02-12T20:08:15.381483+00:00 [running]> on host 1.0.0.127.in-addr.arpa
[2023-02-12T22:08:52.034+0200] {taskinstance.py:1581} INFO - Exporting the following env vars:
AIRFLOW_CTX_DAG_EMAIL=admin@example.com
AIRFLOW_CTX_DAG_OWNER=airflow
AIRFLOW_CTX_DAG_ID=test_process_sales
AIRFLOW_CTX_TASK_ID=ds
AIRFLOW_CTX_EXECUTION_DATE=2023-02-12T20:08:15.381483+00:00
AIRFLOW_CTX_TRY_NUMBER=2
AIRFLOW_CTX_DAG_RUN_ID=manual__2023-02-12T20:08:15.381483+00:00
[2023-02-12T22:08:52.034+0200] {taskinstance.py:1902} ERROR - Task failed with exception
Traceback (most recent call last):
  File "/Users/v.lytvyniuk/Documents/библиотечка/DE online1/git/de_7/lesson_07/airflow_env/lib/python3.8/site-packages/airflow/operators/python.py", line 171, in execute
    return_value = self.execute_callable()
  File "/Users/v.lytvyniuk/Documents/библиотечка/DE online1/git/de_7/lesson_07/airflow_env/lib/python3.8/site-packages/airflow/operators/python.py", line 189, in execute_callable
    return self.python_callable(*self.op_args, **self.op_kwargs)
  File "/Users/v.lytvyniuk/Documents/библиотечка/DE online1/git/de_7/lesson_07/dags/process_sales/main.py", line 52, in ds_func
    date = ti.ds
AttributeError: 'TaskInstance' object has no attribute 'ds'
[2023-02-12T22:08:52.037+0200] {taskinstance.py:1407} INFO - Marking task as UP_FOR_RETRY. dag_id=test_process_sales, task_id=ds, execution_date=20230212T200815, start_date=20230212T200851, end_date=20230212T200852
[2023-02-12T22:08:52.041+0200] {standard_task_runner.py:92} ERROR - Failed to execute job 3687 for task ds ('TaskInstance' object has no attribute 'ds'; 88719)
[2023-02-12T22:08:52.079+0200] {local_task_job.py:156} INFO - Task exited with return code 1
[2023-02-12T22:08:52.092+0200] {local_task_job.py:279} INFO - 0 downstream tasks scheduled from follow-on schedule check
