[2023-02-10T22:36:37.797+0200] {taskinstance.py:1161} INFO - Dependencies not met for <TaskInstance: test_process_sales.extract_data_from_api scheduled__2023-01-10T00:50:00+00:00 [up_for_retry]>, dependency 'Not In Retry Period' FAILED: Task is not ready for retry yet but will be retried automatically. Current date is 2023-02-10T20:36:37.796982+00:00 and task will be retried at 2023-02-10T20:37:02.923650+00:00.
[2023-02-10T22:36:37.802+0200] {local_task_job.py:101} INFO - Task is not able to be run
[2023-02-10T22:37:12.620+0200] {taskinstance.py:1171} INFO - Dependencies all met for <TaskInstance: test_process_sales.extract_data_from_api scheduled__2023-01-10T00:50:00+00:00 [queued]>
[2023-02-10T22:37:12.626+0200] {taskinstance.py:1171} INFO - Dependencies all met for <TaskInstance: test_process_sales.extract_data_from_api scheduled__2023-01-10T00:50:00+00:00 [queued]>
[2023-02-10T22:37:12.626+0200] {taskinstance.py:1368} INFO - 
--------------------------------------------------------------------------------
[2023-02-10T22:37:12.626+0200] {taskinstance.py:1369} INFO - Starting attempt 3 of 4
[2023-02-10T22:37:12.626+0200] {taskinstance.py:1370} INFO - 
--------------------------------------------------------------------------------
[2023-02-10T22:37:12.631+0200] {taskinstance.py:1389} INFO - Executing <Task(PythonOperator): extract_data_from_api> on 2023-01-10 00:50:00+00:00
[2023-02-10T22:37:12.636+0200] {standard_task_runner.py:52} INFO - Started process 11919 to run task
[2023-02-10T22:37:12.639+0200] {standard_task_runner.py:79} INFO - Running: ['airflow', 'tasks', 'run', 'test_process_sales', 'extract_data_from_api', 'scheduled__2023-01-10T00:50:00+00:00', '--job-id', '583', '--raw', '--subdir', 'DAGS_FOLDER/process_sales/mainS.py', '--cfg-path', '/var/folders/1g/4w5x68gx3d92wgygb97jqbd40000gp/T/tmpz91mm8gg', '--error-file', '/var/folders/1g/4w5x68gx3d92wgygb97jqbd40000gp/T/tmpx2dquzdf']
[2023-02-10T22:37:12.641+0200] {standard_task_runner.py:80} INFO - Job 583: Subtask extract_data_from_api
[2023-02-10T22:37:12.669+0200] {task_command.py:371} INFO - Running <TaskInstance: test_process_sales.extract_data_from_api scheduled__2023-01-10T00:50:00+00:00 [running]> on host admins-MacBook-Air-2.local
[2023-02-10T22:37:12.695+0200] {taskinstance.py:1581} INFO - Exporting the following env vars:
AIRFLOW_CTX_DAG_EMAIL=admin@example.com
AIRFLOW_CTX_DAG_OWNER=airflow
AIRFLOW_CTX_DAG_ID=test_process_sales
AIRFLOW_CTX_TASK_ID=extract_data_from_api
AIRFLOW_CTX_EXECUTION_DATE=2023-01-10T00:50:00+00:00
AIRFLOW_CTX_TRY_NUMBER=3
AIRFLOW_CTX_DAG_RUN_ID=scheduled__2023-01-10T00:50:00+00:00
[2023-02-10T22:37:12.695+0200] {extract_data_from_api.py:40} INFO - Your custom error1
[2023-02-10T22:37:12.695+0200] {extract_data_from_api.py:41} INFO - Your custom error2
[2023-02-10T22:37:12.696+0200] {logging_mixin.py:115} INFO - Your custom error3
[2023-02-10T22:37:12.696+0200] {taskinstance.py:1902} ERROR - Task failed with exception
Traceback (most recent call last):
  File "/Users/v.lytvyniuk/Documents/библиотечка/DE online1/git/de_7/lesson_07/airflow_env/lib/python3.8/site-packages/airflow/operators/python.py", line 171, in execute
    return_value = self.execute_callable()
  File "/Users/v.lytvyniuk/Documents/библиотечка/DE online1/git/de_7/lesson_07/airflow_env/lib/python3.8/site-packages/airflow/operators/python.py", line 189, in execute_callable
    return self.python_callable(*self.op_args, **self.op_kwargs)
  File "/Users/v.lytvyniuk/Documents/библиотечка/DE online1/git/de_7/lesson_07/dags/process_sales/extract_data_from_api.py", line 43, in main
    pprint('Your custom error4')
TypeError: 'module' object is not callable
[2023-02-10T22:37:12.699+0200] {taskinstance.py:1407} INFO - Marking task as UP_FOR_RETRY. dag_id=test_process_sales, task_id=extract_data_from_api, execution_date=20230110T005000, start_date=20230210T203712, end_date=20230210T203712
[2023-02-10T22:37:12.703+0200] {standard_task_runner.py:92} ERROR - Failed to execute job 583 for task extract_data_from_api ('module' object is not callable; 11919)
[2023-02-10T22:37:12.741+0200] {local_task_job.py:156} INFO - Task exited with return code 1
[2023-02-10T22:37:12.751+0200] {local_task_job.py:279} INFO - 0 downstream tasks scheduled from follow-on schedule check
