[2023-02-10T22:48:25.958+0200] {taskinstance.py:1171} INFO - Dependencies all met for <TaskInstance: test_process_sales.main2 scheduled__2023-01-10T02:00:00+00:00 [queued]>
[2023-02-10T22:48:25.964+0200] {taskinstance.py:1171} INFO - Dependencies all met for <TaskInstance: test_process_sales.main2 scheduled__2023-01-10T02:00:00+00:00 [queued]>
[2023-02-10T22:48:25.964+0200] {taskinstance.py:1368} INFO - 
--------------------------------------------------------------------------------
[2023-02-10T22:48:25.964+0200] {taskinstance.py:1369} INFO - Starting attempt 2 of 4
[2023-02-10T22:48:25.964+0200] {taskinstance.py:1370} INFO - 
--------------------------------------------------------------------------------
[2023-02-10T22:48:25.969+0200] {taskinstance.py:1389} INFO - Executing <Task(PythonOperator): main2> on 2023-01-10 02:00:00+00:00
[2023-02-10T22:48:25.973+0200] {standard_task_runner.py:52} INFO - Started process 13336 to run task
[2023-02-10T22:48:25.977+0200] {standard_task_runner.py:79} INFO - Running: ['airflow', 'tasks', 'run', 'test_process_sales', 'main2', 'scheduled__2023-01-10T02:00:00+00:00', '--job-id', '687', '--raw', '--subdir', 'DAGS_FOLDER/process_sales/mainS.py', '--cfg-path', '/var/folders/1g/4w5x68gx3d92wgygb97jqbd40000gp/T/tmpsq0r1deq', '--error-file', '/var/folders/1g/4w5x68gx3d92wgygb97jqbd40000gp/T/tmpydqunra9']
[2023-02-10T22:48:25.978+0200] {standard_task_runner.py:80} INFO - Job 687: Subtask main2
[2023-02-10T22:48:26.004+0200] {task_command.py:371} INFO - Running <TaskInstance: test_process_sales.main2 scheduled__2023-01-10T02:00:00+00:00 [running]> on host admins-macbook-air-2.local
[2023-02-10T22:48:26.031+0200] {taskinstance.py:1581} INFO - Exporting the following env vars:
AIRFLOW_CTX_DAG_EMAIL=admin@example.com
AIRFLOW_CTX_DAG_OWNER=airflow
AIRFLOW_CTX_DAG_ID=test_process_sales
AIRFLOW_CTX_TASK_ID=main2
AIRFLOW_CTX_EXECUTION_DATE=2023-01-10T02:00:00+00:00
AIRFLOW_CTX_TRY_NUMBER=2
AIRFLOW_CTX_DAG_RUN_ID=scheduled__2023-01-10T02:00:00+00:00
[2023-02-10T22:48:26.032+0200] {mainS.py:73} INFO - Your custom error1
[2023-02-10T22:48:26.032+0200] {mainS.py:74} INFO - Your custom error2
[2023-02-10T22:48:26.032+0200] {logging_mixin.py:115} INFO - Your custom error3
[2023-02-10T22:48:26.032+0200] {taskinstance.py:1902} ERROR - Task failed with exception
Traceback (most recent call last):
  File "/Users/v.lytvyniuk/Documents/библиотечка/DE online1/git/de_7/lesson_07/airflow_env/lib/python3.8/site-packages/airflow/operators/python.py", line 171, in execute
    return_value = self.execute_callable()
  File "/Users/v.lytvyniuk/Documents/библиотечка/DE online1/git/de_7/lesson_07/airflow_env/lib/python3.8/site-packages/airflow/operators/python.py", line 189, in execute_callable
    return self.python_callable(*self.op_args, **self.op_kwargs)
  File "/Users/v.lytvyniuk/Documents/библиотечка/DE online1/git/de_7/lesson_07/dags/process_sales/mainS.py", line 76, in main2
    pprint('Your custom error4')
TypeError: 'module' object is not callable
[2023-02-10T22:48:26.035+0200] {taskinstance.py:1407} INFO - Marking task as UP_FOR_RETRY. dag_id=test_process_sales, task_id=main2, execution_date=20230110T020000, start_date=20230210T204825, end_date=20230210T204826
[2023-02-10T22:48:26.039+0200] {standard_task_runner.py:92} ERROR - Failed to execute job 687 for task main2 ('module' object is not callable; 13336)
[2023-02-10T22:48:26.082+0200] {local_task_job.py:156} INFO - Task exited with return code 1
[2023-02-10T22:48:26.096+0200] {local_task_job.py:279} INFO - 0 downstream tasks scheduled from follow-on schedule check
