[2023-02-10T22:31:35.772+0200] {taskinstance.py:1171} INFO - Dependencies all met for <TaskInstance: test_process_sales.extract_data_from_api scheduled__2023-01-09T21:35:00+00:00 [queued]>
[2023-02-10T22:31:35.778+0200] {taskinstance.py:1171} INFO - Dependencies all met for <TaskInstance: test_process_sales.extract_data_from_api scheduled__2023-01-09T21:35:00+00:00 [queued]>
[2023-02-10T22:31:35.778+0200] {taskinstance.py:1368} INFO - 
--------------------------------------------------------------------------------
[2023-02-10T22:31:35.778+0200] {taskinstance.py:1369} INFO - Starting attempt 2 of 4
[2023-02-10T22:31:35.778+0200] {taskinstance.py:1370} INFO - 
--------------------------------------------------------------------------------
[2023-02-10T22:31:35.783+0200] {taskinstance.py:1389} INFO - Executing <Task(PythonOperator): extract_data_from_api> on 2023-01-09 21:35:00+00:00
[2023-02-10T22:31:35.787+0200] {standard_task_runner.py:52} INFO - Started process 10296 to run task
[2023-02-10T22:31:35.790+0200] {standard_task_runner.py:79} INFO - Running: ['airflow', 'tasks', 'run', 'test_process_sales', 'extract_data_from_api', 'scheduled__2023-01-09T21:35:00+00:00', '--job-id', '351', '--raw', '--subdir', 'DAGS_FOLDER/process_sales/mainS.py', '--cfg-path', '/var/folders/1g/4w5x68gx3d92wgygb97jqbd40000gp/T/tmpgz9aems9', '--error-file', '/var/folders/1g/4w5x68gx3d92wgygb97jqbd40000gp/T/tmpeypddo6_']
[2023-02-10T22:31:35.791+0200] {standard_task_runner.py:80} INFO - Job 351: Subtask extract_data_from_api
[2023-02-10T22:31:35.817+0200] {task_command.py:371} INFO - Running <TaskInstance: test_process_sales.extract_data_from_api scheduled__2023-01-09T21:35:00+00:00 [running]> on host admins-MacBook-Air-2.local
[2023-02-10T22:31:35.841+0200] {taskinstance.py:1581} INFO - Exporting the following env vars:
AIRFLOW_CTX_DAG_EMAIL=admin@example.com
AIRFLOW_CTX_DAG_OWNER=airflow
AIRFLOW_CTX_DAG_ID=test_process_sales
AIRFLOW_CTX_TASK_ID=extract_data_from_api
AIRFLOW_CTX_EXECUTION_DATE=2023-01-09T21:35:00+00:00
AIRFLOW_CTX_TRY_NUMBER=2
AIRFLOW_CTX_DAG_RUN_ID=scheduled__2023-01-09T21:35:00+00:00
[2023-02-10T22:31:35.842+0200] {extract_data_from_api.py:40} INFO - Your custom error1
[2023-02-10T22:31:35.842+0200] {extract_data_from_api.py:41} INFO - Your custom error2
[2023-02-10T22:31:35.842+0200] {logging_mixin.py:115} INFO - Your custom error3
[2023-02-10T22:31:35.843+0200] {taskinstance.py:1902} ERROR - Task failed with exception
Traceback (most recent call last):
  File "/Users/v.lytvyniuk/Documents/библиотечка/DE online1/git/de_7/lesson_07/airflow_env/lib/python3.8/site-packages/airflow/operators/python.py", line 171, in execute
    return_value = self.execute_callable()
  File "/Users/v.lytvyniuk/Documents/библиотечка/DE online1/git/de_7/lesson_07/airflow_env/lib/python3.8/site-packages/airflow/operators/python.py", line 189, in execute_callable
    return self.python_callable(*self.op_args, **self.op_kwargs)
  File "/Users/v.lytvyniuk/Documents/библиотечка/DE online1/git/de_7/lesson_07/dags/process_sales/extract_data_from_api.py", line 43, in main
    pprint('Your custom error4')
TypeError: 'module' object is not callable
[2023-02-10T22:31:35.845+0200] {taskinstance.py:1407} INFO - Marking task as UP_FOR_RETRY. dag_id=test_process_sales, task_id=extract_data_from_api, execution_date=20230109T213500, start_date=20230210T203135, end_date=20230210T203135
[2023-02-10T22:31:35.849+0200] {standard_task_runner.py:92} ERROR - Failed to execute job 351 for task extract_data_from_api ('module' object is not callable; 10296)
[2023-02-10T22:31:35.852+0200] {local_task_job.py:156} INFO - Task exited with return code 1
[2023-02-10T22:31:35.861+0200] {local_task_job.py:279} INFO - 0 downstream tasks scheduled from follow-on schedule check
