[2023-02-13T20:36:04.804+0200] {taskinstance.py:1171} INFO - Dependencies all met for <TaskInstance: test_process_sales.extract_data_from_api scheduled__2023-02-13T03:26:00+00:00 [queued]>
[2023-02-13T20:36:04.814+0200] {taskinstance.py:1171} INFO - Dependencies all met for <TaskInstance: test_process_sales.extract_data_from_api scheduled__2023-02-13T03:26:00+00:00 [queued]>
[2023-02-13T20:36:04.815+0200] {taskinstance.py:1368} INFO - 
--------------------------------------------------------------------------------
[2023-02-13T20:36:04.815+0200] {taskinstance.py:1369} INFO - Starting attempt 1 of 4
[2023-02-13T20:36:04.815+0200] {taskinstance.py:1370} INFO - 
--------------------------------------------------------------------------------
[2023-02-13T20:36:04.820+0200] {taskinstance.py:1389} INFO - Executing <Task(PythonOperator): extract_data_from_api> on 2023-02-13 03:26:00+00:00
[2023-02-13T20:36:04.824+0200] {standard_task_runner.py:52} INFO - Started process 42509 to run task
[2023-02-13T20:36:04.827+0200] {standard_task_runner.py:79} INFO - Running: ['airflow', 'tasks', 'run', 'test_process_sales', 'extract_data_from_api', 'scheduled__2023-02-13T03:26:00+00:00', '--job-id', '3820', '--raw', '--subdir', 'DAGS_FOLDER/process_sales/main.py', '--cfg-path', '/var/folders/1g/4w5x68gx3d92wgygb97jqbd40000gp/T/tmpix_cd_4w', '--error-file', '/var/folders/1g/4w5x68gx3d92wgygb97jqbd40000gp/T/tmp01nu9b0l']
[2023-02-13T20:36:04.828+0200] {standard_task_runner.py:80} INFO - Job 3820: Subtask extract_data_from_api
[2023-02-13T20:36:04.861+0200] {task_command.py:371} INFO - Running <TaskInstance: test_process_sales.extract_data_from_api scheduled__2023-02-13T03:26:00+00:00 [running]> on host 1.0.0.0.0.0.0.0.0.0.0.0.0.0.0.0.0.0.0.0.0.0.0.0.0.0.0.0.0.0.0.0.ip6.arpa
[2023-02-13T20:36:04.898+0200] {taskinstance.py:1581} INFO - Exporting the following env vars:
AIRFLOW_CTX_DAG_EMAIL=admin@example.com
AIRFLOW_CTX_DAG_OWNER=airflow
AIRFLOW_CTX_DAG_ID=test_process_sales
AIRFLOW_CTX_TASK_ID=extract_data_from_api
AIRFLOW_CTX_EXECUTION_DATE=2023-02-13T03:26:00+00:00
AIRFLOW_CTX_TRY_NUMBER=1
AIRFLOW_CTX_DAG_RUN_ID=scheduled__2023-02-13T03:26:00+00:00
[2023-02-13T20:36:04.902+0200] {taskinstance.py:1902} ERROR - Task failed with exception
Traceback (most recent call last):
  File "/Users/v.lytvyniuk/Documents/библиотечка/DE online1/git/de_7/lesson_07/airflow_env/lib/python3.8/site-packages/urllib3/connection.py", line 174, in _new_conn
    conn = connection.create_connection(
  File "/Users/v.lytvyniuk/Documents/библиотечка/DE online1/git/de_7/lesson_07/airflow_env/lib/python3.8/site-packages/urllib3/util/connection.py", line 72, in create_connection
    for res in socket.getaddrinfo(host, port, family, socket.SOCK_STREAM):
  File "/Users/v.lytvyniuk/opt/anaconda3/lib/python3.8/socket.py", line 918, in getaddrinfo
    for res in _socket.getaddrinfo(host, port, family, type, proto, flags):
socket.gaierror: [Errno 8] nodename nor servname provided, or not known

During handling of the above exception, another exception occurred:

Traceback (most recent call last):
  File "/Users/v.lytvyniuk/Documents/библиотечка/DE online1/git/de_7/lesson_07/airflow_env/lib/python3.8/site-packages/urllib3/connectionpool.py", line 703, in urlopen
    httplib_response = self._make_request(
  File "/Users/v.lytvyniuk/Documents/библиотечка/DE online1/git/de_7/lesson_07/airflow_env/lib/python3.8/site-packages/urllib3/connectionpool.py", line 386, in _make_request
    self._validate_conn(conn)
  File "/Users/v.lytvyniuk/Documents/библиотечка/DE online1/git/de_7/lesson_07/airflow_env/lib/python3.8/site-packages/urllib3/connectionpool.py", line 1042, in _validate_conn
    conn.connect()
  File "/Users/v.lytvyniuk/Documents/библиотечка/DE online1/git/de_7/lesson_07/airflow_env/lib/python3.8/site-packages/urllib3/connection.py", line 358, in connect
    self.sock = conn = self._new_conn()
  File "/Users/v.lytvyniuk/Documents/библиотечка/DE online1/git/de_7/lesson_07/airflow_env/lib/python3.8/site-packages/urllib3/connection.py", line 186, in _new_conn
    raise NewConnectionError(
urllib3.exceptions.NewConnectionError: <urllib3.connection.HTTPSConnection object at 0x7f87c266c700>: Failed to establish a new connection: [Errno 8] nodename nor servname provided, or not known

During handling of the above exception, another exception occurred:

Traceback (most recent call last):
  File "/Users/v.lytvyniuk/Documents/библиотечка/DE online1/git/de_7/lesson_07/airflow_env/lib/python3.8/site-packages/requests/adapters.py", line 489, in send
    resp = conn.urlopen(
  File "/Users/v.lytvyniuk/Documents/библиотечка/DE online1/git/de_7/lesson_07/airflow_env/lib/python3.8/site-packages/urllib3/connectionpool.py", line 787, in urlopen
    retries = retries.increment(
  File "/Users/v.lytvyniuk/Documents/библиотечка/DE online1/git/de_7/lesson_07/airflow_env/lib/python3.8/site-packages/urllib3/util/retry.py", line 592, in increment
    raise MaxRetryError(_pool, url, error or ResponseError(cause))
urllib3.exceptions.MaxRetryError: HTTPSConnectionPool(host='fake-api-vycpfa6oca-uc.a.run.app', port=443): Max retries exceeded with url: /sales?date=2022-08-09&page=1 (Caused by NewConnectionError('<urllib3.connection.HTTPSConnection object at 0x7f87c266c700>: Failed to establish a new connection: [Errno 8] nodename nor servname provided, or not known'))

During handling of the above exception, another exception occurred:

Traceback (most recent call last):
  File "/Users/v.lytvyniuk/Documents/библиотечка/DE online1/git/de_7/lesson_07/airflow_env/lib/python3.8/site-packages/airflow/operators/python.py", line 171, in execute
    return_value = self.execute_callable()
  File "/Users/v.lytvyniuk/Documents/библиотечка/DE online1/git/de_7/lesson_07/airflow_env/lib/python3.8/site-packages/airflow/operators/python.py", line 189, in execute_callable
    return self.python_callable(*self.op_args, **self.op_kwargs)
  File "/Users/v.lytvyniuk/Documents/библиотечка/DE online1/git/de_7/lesson_07/dags/process_sales/extract_data_from_api.py", line 27, in main
    data = get_request_to_api(FAKE_API_URL, FAKE_API_HEADERS, PARAMS)
  File "/Users/v.lytvyniuk/Documents/библиотечка/DE online1/git/de_7/lesson_07/dags/process_sales/extract_data_from_api.py", line 16, in get_request_to_api
    data = requests.get(url, headers=headers, params=params)
  File "/Users/v.lytvyniuk/Documents/библиотечка/DE online1/git/de_7/lesson_07/airflow_env/lib/python3.8/site-packages/requests/api.py", line 73, in get
    return request("get", url, params=params, **kwargs)
  File "/Users/v.lytvyniuk/Documents/библиотечка/DE online1/git/de_7/lesson_07/airflow_env/lib/python3.8/site-packages/requests/api.py", line 59, in request
    return session.request(method=method, url=url, **kwargs)
  File "/Users/v.lytvyniuk/Documents/библиотечка/DE online1/git/de_7/lesson_07/airflow_env/lib/python3.8/site-packages/requests/sessions.py", line 587, in request
    resp = self.send(prep, **send_kwargs)
  File "/Users/v.lytvyniuk/Documents/библиотечка/DE online1/git/de_7/lesson_07/airflow_env/lib/python3.8/site-packages/requests/sessions.py", line 701, in send
    r = adapter.send(request, **kwargs)
  File "/Users/v.lytvyniuk/Documents/библиотечка/DE online1/git/de_7/lesson_07/airflow_env/lib/python3.8/site-packages/requests/adapters.py", line 565, in send
    raise ConnectionError(e, request=request)
requests.exceptions.ConnectionError: HTTPSConnectionPool(host='fake-api-vycpfa6oca-uc.a.run.app', port=443): Max retries exceeded with url: /sales?date=2022-08-09&page=1 (Caused by NewConnectionError('<urllib3.connection.HTTPSConnection object at 0x7f87c266c700>: Failed to establish a new connection: [Errno 8] nodename nor servname provided, or not known'))
[2023-02-13T20:36:04.907+0200] {taskinstance.py:1407} INFO - Marking task as UP_FOR_RETRY. dag_id=test_process_sales, task_id=extract_data_from_api, execution_date=20230213T032600, start_date=20230213T183604, end_date=20230213T183604
[2023-02-13T20:36:04.911+0200] {standard_task_runner.py:92} ERROR - Failed to execute job 3820 for task extract_data_from_api (HTTPSConnectionPool(host='fake-api-vycpfa6oca-uc.a.run.app', port=443): Max retries exceeded with url: /sales?date=2022-08-09&page=1 (Caused by NewConnectionError('<urllib3.connection.HTTPSConnection object at 0x7f87c266c700>: Failed to establish a new connection: [Errno 8] nodename nor servname provided, or not known')); 42509)
[2023-02-13T20:36:04.945+0200] {local_task_job.py:156} INFO - Task exited with return code 1
[2023-02-13T20:36:04.960+0200] {local_task_job.py:279} INFO - 0 downstream tasks scheduled from follow-on schedule check
