[2023-02-12T22:09:19.058+0200] {taskinstance.py:1171} INFO - Dependencies all met for <TaskInstance: test_process_sales.ds scheduled__2023-02-12T19:25:00+00:00 [queued]>
[2023-02-12T22:09:19.066+0200] {taskinstance.py:1171} INFO - Dependencies all met for <TaskInstance: test_process_sales.ds scheduled__2023-02-12T19:25:00+00:00 [queued]>
[2023-02-12T22:09:19.066+0200] {taskinstance.py:1368} INFO - 
--------------------------------------------------------------------------------
[2023-02-12T22:09:19.066+0200] {taskinstance.py:1369} INFO - Starting attempt 4 of 4
[2023-02-12T22:09:19.066+0200] {taskinstance.py:1370} INFO - 
--------------------------------------------------------------------------------
[2023-02-12T22:09:19.071+0200] {taskinstance.py:1389} INFO - Executing <Task(PythonOperator): ds> on 2023-02-12 19:25:00+00:00
[2023-02-12T22:09:19.076+0200] {standard_task_runner.py:52} INFO - Started process 88850 to run task
[2023-02-12T22:09:19.079+0200] {standard_task_runner.py:79} INFO - Running: ['airflow', 'tasks', 'run', 'test_process_sales', 'ds', 'scheduled__2023-02-12T19:25:00+00:00', '--job-id', '3697', '--raw', '--subdir', 'DAGS_FOLDER/process_sales/main.py', '--cfg-path', '/var/folders/1g/4w5x68gx3d92wgygb97jqbd40000gp/T/tmpjf7llgqp', '--error-file', '/var/folders/1g/4w5x68gx3d92wgygb97jqbd40000gp/T/tmp4cfq7bys']
[2023-02-12T22:09:19.081+0200] {standard_task_runner.py:80} INFO - Job 3697: Subtask ds
[2023-02-12T22:09:19.108+0200] {task_command.py:371} INFO - Running <TaskInstance: test_process_sales.ds scheduled__2023-02-12T19:25:00+00:00 [running]> on host 1.0.0.127.in-addr.arpa
[2023-02-12T22:09:19.143+0200] {taskinstance.py:1581} INFO - Exporting the following env vars:
AIRFLOW_CTX_DAG_EMAIL=admin@example.com
AIRFLOW_CTX_DAG_OWNER=airflow
AIRFLOW_CTX_DAG_ID=test_process_sales
AIRFLOW_CTX_TASK_ID=ds
AIRFLOW_CTX_EXECUTION_DATE=2023-02-12T19:25:00+00:00
AIRFLOW_CTX_TRY_NUMBER=4
AIRFLOW_CTX_DAG_RUN_ID=scheduled__2023-02-12T19:25:00+00:00
[2023-02-12T22:09:19.144+0200] {taskinstance.py:1902} ERROR - Task failed with exception
Traceback (most recent call last):
  File "/Users/v.lytvyniuk/Documents/библиотечка/DE online1/git/de_7/lesson_07/airflow_env/lib/python3.8/site-packages/airflow/operators/python.py", line 171, in execute
    return_value = self.execute_callable()
  File "/Users/v.lytvyniuk/Documents/библиотечка/DE online1/git/de_7/lesson_07/airflow_env/lib/python3.8/site-packages/airflow/operators/python.py", line 189, in execute_callable
    return self.python_callable(*self.op_args, **self.op_kwargs)
  File "/Users/v.lytvyniuk/Documents/библиотечка/DE online1/git/de_7/lesson_07/dags/process_sales/main.py", line 52, in ds_func
    date = ti.ds
AttributeError: 'TaskInstance' object has no attribute 'ds'
[2023-02-12T22:09:19.146+0200] {taskinstance.py:1407} INFO - Marking task as FAILED. dag_id=test_process_sales, task_id=ds, execution_date=20230212T192500, start_date=20230212T200919, end_date=20230212T200919
[2023-02-12T22:09:19.151+0200] {standard_task_runner.py:92} ERROR - Failed to execute job 3697 for task ds ('TaskInstance' object has no attribute 'ds'; 88850)
[2023-02-12T22:09:19.184+0200] {local_task_job.py:156} INFO - Task exited with return code 1
[2023-02-12T22:09:19.196+0200] {local_task_job.py:279} INFO - 0 downstream tasks scheduled from follow-on schedule check
