[2023-02-10T22:36:17.135+0200] {taskinstance.py:1171} INFO - Dependencies all met for <TaskInstance: test_process_sales.main2 scheduled__2023-01-10T00:25:00+00:00 [queued]>
[2023-02-10T22:36:17.141+0200] {taskinstance.py:1171} INFO - Dependencies all met for <TaskInstance: test_process_sales.main2 scheduled__2023-01-10T00:25:00+00:00 [queued]>
[2023-02-10T22:36:17.141+0200] {taskinstance.py:1368} INFO - 
--------------------------------------------------------------------------------
[2023-02-10T22:36:17.141+0200] {taskinstance.py:1369} INFO - Starting attempt 1 of 4
[2023-02-10T22:36:17.141+0200] {taskinstance.py:1370} INFO - 
--------------------------------------------------------------------------------
[2023-02-10T22:36:17.146+0200] {taskinstance.py:1389} INFO - Executing <Task(PythonOperator): main2> on 2023-01-10 00:25:00+00:00
[2023-02-10T22:36:17.150+0200] {standard_task_runner.py:52} INFO - Started process 11628 to run task
[2023-02-10T22:36:17.153+0200] {standard_task_runner.py:79} INFO - Running: ['airflow', 'tasks', 'run', 'test_process_sales', 'main2', 'scheduled__2023-01-10T00:25:00+00:00', '--job-id', '529', '--raw', '--subdir', 'DAGS_FOLDER/process_sales/mainS.py', '--cfg-path', '/var/folders/1g/4w5x68gx3d92wgygb97jqbd40000gp/T/tmpsp6co2z1', '--error-file', '/var/folders/1g/4w5x68gx3d92wgygb97jqbd40000gp/T/tmp1t_y93pj']
[2023-02-10T22:36:17.154+0200] {standard_task_runner.py:80} INFO - Job 529: Subtask main2
[2023-02-10T22:36:17.180+0200] {task_command.py:371} INFO - Running <TaskInstance: test_process_sales.main2 scheduled__2023-01-10T00:25:00+00:00 [running]> on host admins-MacBook-Air-2.local
[2023-02-10T22:36:17.208+0200] {taskinstance.py:1581} INFO - Exporting the following env vars:
AIRFLOW_CTX_DAG_EMAIL=admin@example.com
AIRFLOW_CTX_DAG_OWNER=airflow
AIRFLOW_CTX_DAG_ID=test_process_sales
AIRFLOW_CTX_TASK_ID=main2
AIRFLOW_CTX_EXECUTION_DATE=2023-01-10T00:25:00+00:00
AIRFLOW_CTX_TRY_NUMBER=1
AIRFLOW_CTX_DAG_RUN_ID=scheduled__2023-01-10T00:25:00+00:00
[2023-02-10T22:36:17.209+0200] {mainS.py:73} INFO - Your custom error1
[2023-02-10T22:36:17.209+0200] {mainS.py:74} INFO - Your custom error2
[2023-02-10T22:36:17.209+0200] {logging_mixin.py:115} INFO - Your custom error3
[2023-02-10T22:36:17.209+0200] {taskinstance.py:1902} ERROR - Task failed with exception
Traceback (most recent call last):
  File "/Users/v.lytvyniuk/Documents/библиотечка/DE online1/git/de_7/lesson_07/airflow_env/lib/python3.8/site-packages/airflow/operators/python.py", line 171, in execute
    return_value = self.execute_callable()
  File "/Users/v.lytvyniuk/Documents/библиотечка/DE online1/git/de_7/lesson_07/airflow_env/lib/python3.8/site-packages/airflow/operators/python.py", line 189, in execute_callable
    return self.python_callable(*self.op_args, **self.op_kwargs)
  File "/Users/v.lytvyniuk/Documents/библиотечка/DE online1/git/de_7/lesson_07/dags/process_sales/mainS.py", line 76, in main2
    pprint('Your custom error4')
TypeError: 'module' object is not callable
[2023-02-10T22:36:17.212+0200] {taskinstance.py:1407} INFO - Marking task as UP_FOR_RETRY. dag_id=test_process_sales, task_id=main2, execution_date=20230110T002500, start_date=20230210T203617, end_date=20230210T203617
[2023-02-10T22:36:17.216+0200] {standard_task_runner.py:92} ERROR - Failed to execute job 529 for task main2 ('module' object is not callable; 11628)
[2023-02-10T22:36:17.258+0200] {local_task_job.py:156} INFO - Task exited with return code 1
[2023-02-10T22:36:17.270+0200] {local_task_job.py:279} INFO - 0 downstream tasks scheduled from follow-on schedule check
