[2023-02-18T22:09:54.409+0200] {taskinstance.py:1171} INFO - Dependencies all met for <TaskInstance: test_process_sales2.format_data_to_avro scheduled__2023-02-08T03:07:00+00:00 [queued]>
[2023-02-18T22:09:54.415+0200] {taskinstance.py:1171} INFO - Dependencies all met for <TaskInstance: test_process_sales2.format_data_to_avro scheduled__2023-02-08T03:07:00+00:00 [queued]>
[2023-02-18T22:09:54.415+0200] {taskinstance.py:1368} INFO - 
--------------------------------------------------------------------------------
[2023-02-18T22:09:54.415+0200] {taskinstance.py:1369} INFO - Starting attempt 1 of 4
[2023-02-18T22:09:54.415+0200] {taskinstance.py:1370} INFO - 
--------------------------------------------------------------------------------
[2023-02-18T22:09:54.420+0200] {taskinstance.py:1389} INFO - Executing <Task(PythonOperator): format_data_to_avro> on 2023-02-08 03:07:00+00:00
[2023-02-18T22:09:54.424+0200] {standard_task_runner.py:52} INFO - Started process 30214 to run task
[2023-02-18T22:09:54.428+0200] {standard_task_runner.py:79} INFO - Running: ['airflow', 'tasks', 'run', 'test_process_sales2', 'format_data_to_avro', 'scheduled__2023-02-08T03:07:00+00:00', '--job-id', '4856', '--raw', '--subdir', 'DAGS_FOLDER/process_sales/main2.py', '--cfg-path', '/var/folders/1g/4w5x68gx3d92wgygb97jqbd40000gp/T/tmpy73rj4c4', '--error-file', '/var/folders/1g/4w5x68gx3d92wgygb97jqbd40000gp/T/tmp2p5d5n15']
[2023-02-18T22:09:54.429+0200] {standard_task_runner.py:80} INFO - Job 4856: Subtask format_data_to_avro
[2023-02-18T22:09:54.455+0200] {task_command.py:371} INFO - Running <TaskInstance: test_process_sales2.format_data_to_avro scheduled__2023-02-08T03:07:00+00:00 [running]> on host 1.0.0.0.0.0.0.0.0.0.0.0.0.0.0.0.0.0.0.0.0.0.0.0.0.0.0.0.0.0.0.0.ip6.arpa
[2023-02-18T22:09:54.491+0200] {taskinstance.py:1581} INFO - Exporting the following env vars:
AIRFLOW_CTX_DAG_EMAIL=admin@example.com
AIRFLOW_CTX_DAG_OWNER=airflow
AIRFLOW_CTX_DAG_ID=test_process_sales2
AIRFLOW_CTX_TASK_ID=format_data_to_avro
AIRFLOW_CTX_EXECUTION_DATE=2023-02-08T03:07:00+00:00
AIRFLOW_CTX_TRY_NUMBER=1
AIRFLOW_CTX_DAG_RUN_ID=scheduled__2023-02-08T03:07:00+00:00
[2023-02-18T22:09:54.494+0200] {taskinstance.py:1902} ERROR - Task failed with exception
Traceback (most recent call last):
  File "/Users/v.lytvyniuk/Documents/библиотечка/DE online1/git/de_7/lesson_07/airflow_env/lib/python3.8/site-packages/airflow/operators/python.py", line 171, in execute
    return_value = self.execute_callable()
  File "/Users/v.lytvyniuk/Documents/библиотечка/DE online1/git/de_7/lesson_07/airflow_env/lib/python3.8/site-packages/airflow/operators/python.py", line 189, in execute_callable
    return self.python_callable(*self.op_args, **self.op_kwargs)
  File "/Users/v.lytvyniuk/Documents/библиотечка/DE online1/git/de_7/lesson_07/dags/process_sales/main2.py", line 57, in format_data_to_avro
    for d in data['data']
KeyError: 'data'
[2023-02-18T22:09:54.496+0200] {taskinstance.py:1407} INFO - Marking task as UP_FOR_RETRY. dag_id=test_process_sales2, task_id=format_data_to_avro, execution_date=20230208T030700, start_date=20230218T200954, end_date=20230218T200954
[2023-02-18T22:09:54.501+0200] {standard_task_runner.py:92} ERROR - Failed to execute job 4856 for task format_data_to_avro ('data'; 30214)
[2023-02-18T22:09:54.530+0200] {local_task_job.py:156} INFO - Task exited with return code 1
[2023-02-18T22:09:54.542+0200] {local_task_job.py:279} INFO - 0 downstream tasks scheduled from follow-on schedule check
