[2023-02-12T22:08:53.412+0200] {taskinstance.py:1171} INFO - Dependencies all met for <TaskInstance: test_process_sales.ds scheduled__2023-02-12T19:35:00+00:00 [queued]>
[2023-02-12T22:08:53.417+0200] {taskinstance.py:1171} INFO - Dependencies all met for <TaskInstance: test_process_sales.ds scheduled__2023-02-12T19:35:00+00:00 [queued]>
[2023-02-12T22:08:53.418+0200] {taskinstance.py:1368} INFO - 
--------------------------------------------------------------------------------
[2023-02-12T22:08:53.418+0200] {taskinstance.py:1369} INFO - Starting attempt 3 of 4
[2023-02-12T22:08:53.418+0200] {taskinstance.py:1370} INFO - 
--------------------------------------------------------------------------------
[2023-02-12T22:08:53.423+0200] {taskinstance.py:1389} INFO - Executing <Task(PythonOperator): ds> on 2023-02-12 19:35:00+00:00
[2023-02-12T22:08:53.427+0200] {standard_task_runner.py:52} INFO - Started process 88725 to run task
[2023-02-12T22:08:53.430+0200] {standard_task_runner.py:79} INFO - Running: ['airflow', 'tasks', 'run', 'test_process_sales', 'ds', 'scheduled__2023-02-12T19:35:00+00:00', '--job-id', '3688', '--raw', '--subdir', 'DAGS_FOLDER/process_sales/main.py', '--cfg-path', '/var/folders/1g/4w5x68gx3d92wgygb97jqbd40000gp/T/tmp33ui8t9o', '--error-file', '/var/folders/1g/4w5x68gx3d92wgygb97jqbd40000gp/T/tmp4t16pf4f']
[2023-02-12T22:08:53.431+0200] {standard_task_runner.py:80} INFO - Job 3688: Subtask ds
[2023-02-12T22:08:53.458+0200] {task_command.py:371} INFO - Running <TaskInstance: test_process_sales.ds scheduled__2023-02-12T19:35:00+00:00 [running]> on host 1.0.0.127.in-addr.arpa
[2023-02-12T22:08:53.493+0200] {taskinstance.py:1581} INFO - Exporting the following env vars:
AIRFLOW_CTX_DAG_EMAIL=admin@example.com
AIRFLOW_CTX_DAG_OWNER=airflow
AIRFLOW_CTX_DAG_ID=test_process_sales
AIRFLOW_CTX_TASK_ID=ds
AIRFLOW_CTX_EXECUTION_DATE=2023-02-12T19:35:00+00:00
AIRFLOW_CTX_TRY_NUMBER=3
AIRFLOW_CTX_DAG_RUN_ID=scheduled__2023-02-12T19:35:00+00:00
[2023-02-12T22:08:53.494+0200] {taskinstance.py:1902} ERROR - Task failed with exception
Traceback (most recent call last):
  File "/Users/v.lytvyniuk/Documents/библиотечка/DE online1/git/de_7/lesson_07/airflow_env/lib/python3.8/site-packages/airflow/operators/python.py", line 171, in execute
    return_value = self.execute_callable()
  File "/Users/v.lytvyniuk/Documents/библиотечка/DE online1/git/de_7/lesson_07/airflow_env/lib/python3.8/site-packages/airflow/operators/python.py", line 189, in execute_callable
    return self.python_callable(*self.op_args, **self.op_kwargs)
  File "/Users/v.lytvyniuk/Documents/библиотечка/DE online1/git/de_7/lesson_07/dags/process_sales/main.py", line 52, in ds_func
    date = ti.ds
AttributeError: 'TaskInstance' object has no attribute 'ds'
[2023-02-12T22:08:53.496+0200] {taskinstance.py:1407} INFO - Marking task as UP_FOR_RETRY. dag_id=test_process_sales, task_id=ds, execution_date=20230212T193500, start_date=20230212T200853, end_date=20230212T200853
[2023-02-12T22:08:53.500+0200] {standard_task_runner.py:92} ERROR - Failed to execute job 3688 for task ds ('TaskInstance' object has no attribute 'ds'; 88725)
[2023-02-12T22:08:53.532+0200] {local_task_job.py:156} INFO - Task exited with return code 1
[2023-02-12T22:08:53.544+0200] {local_task_job.py:279} INFO - 0 downstream tasks scheduled from follow-on schedule check
