[2023-02-10T22:37:04.914+0200] {taskinstance.py:1171} INFO - Dependencies all met for <TaskInstance: test_process_sales.main2 scheduled__2023-01-10T01:05:00+00:00 [queued]>
[2023-02-10T22:37:04.920+0200] {taskinstance.py:1171} INFO - Dependencies all met for <TaskInstance: test_process_sales.main2 scheduled__2023-01-10T01:05:00+00:00 [queued]>
[2023-02-10T22:37:04.920+0200] {taskinstance.py:1368} INFO - 
--------------------------------------------------------------------------------
[2023-02-10T22:37:04.920+0200] {taskinstance.py:1369} INFO - Starting attempt 2 of 4
[2023-02-10T22:37:04.920+0200] {taskinstance.py:1370} INFO - 
--------------------------------------------------------------------------------
[2023-02-10T22:37:04.925+0200] {taskinstance.py:1389} INFO - Executing <Task(PythonOperator): main2> on 2023-01-10 01:05:00+00:00
[2023-02-10T22:37:04.929+0200] {standard_task_runner.py:52} INFO - Started process 11880 to run task
[2023-02-10T22:37:04.932+0200] {standard_task_runner.py:79} INFO - Running: ['airflow', 'tasks', 'run', 'test_process_sales', 'main2', 'scheduled__2023-01-10T01:05:00+00:00', '--job-id', '575', '--raw', '--subdir', 'DAGS_FOLDER/process_sales/mainS.py', '--cfg-path', '/var/folders/1g/4w5x68gx3d92wgygb97jqbd40000gp/T/tmp471pz0vy', '--error-file', '/var/folders/1g/4w5x68gx3d92wgygb97jqbd40000gp/T/tmpf93lqsdm']
[2023-02-10T22:37:04.933+0200] {standard_task_runner.py:80} INFO - Job 575: Subtask main2
[2023-02-10T22:37:04.960+0200] {task_command.py:371} INFO - Running <TaskInstance: test_process_sales.main2 scheduled__2023-01-10T01:05:00+00:00 [running]> on host admins-MacBook-Air-2.local
[2023-02-10T22:37:04.985+0200] {taskinstance.py:1581} INFO - Exporting the following env vars:
AIRFLOW_CTX_DAG_EMAIL=admin@example.com
AIRFLOW_CTX_DAG_OWNER=airflow
AIRFLOW_CTX_DAG_ID=test_process_sales
AIRFLOW_CTX_TASK_ID=main2
AIRFLOW_CTX_EXECUTION_DATE=2023-01-10T01:05:00+00:00
AIRFLOW_CTX_TRY_NUMBER=2
AIRFLOW_CTX_DAG_RUN_ID=scheduled__2023-01-10T01:05:00+00:00
[2023-02-10T22:37:04.985+0200] {mainS.py:73} INFO - Your custom error1
[2023-02-10T22:37:04.985+0200] {mainS.py:74} INFO - Your custom error2
[2023-02-10T22:37:04.986+0200] {logging_mixin.py:115} INFO - Your custom error3
[2023-02-10T22:37:04.986+0200] {taskinstance.py:1902} ERROR - Task failed with exception
Traceback (most recent call last):
  File "/Users/v.lytvyniuk/Documents/библиотечка/DE online1/git/de_7/lesson_07/airflow_env/lib/python3.8/site-packages/airflow/operators/python.py", line 171, in execute
    return_value = self.execute_callable()
  File "/Users/v.lytvyniuk/Documents/библиотечка/DE online1/git/de_7/lesson_07/airflow_env/lib/python3.8/site-packages/airflow/operators/python.py", line 189, in execute_callable
    return self.python_callable(*self.op_args, **self.op_kwargs)
  File "/Users/v.lytvyniuk/Documents/библиотечка/DE online1/git/de_7/lesson_07/dags/process_sales/mainS.py", line 76, in main2
    pprint('Your custom error4')
TypeError: 'module' object is not callable
[2023-02-10T22:37:04.988+0200] {taskinstance.py:1407} INFO - Marking task as UP_FOR_RETRY. dag_id=test_process_sales, task_id=main2, execution_date=20230110T010500, start_date=20230210T203704, end_date=20230210T203704
[2023-02-10T22:37:04.992+0200] {standard_task_runner.py:92} ERROR - Failed to execute job 575 for task main2 ('module' object is not callable; 11880)
[2023-02-10T22:37:05.039+0200] {local_task_job.py:156} INFO - Task exited with return code 1
[2023-02-10T22:37:05.051+0200] {local_task_job.py:279} INFO - 0 downstream tasks scheduled from follow-on schedule check
